<?xml version="1.0"?>
<robot name="TLTPillar">
  <material name="blue">
    <color rgba="0 0 0.8 100"/>
  </material>

  <material name="white">
    <color rgba="1 1 1 100"/>
  </material>
  <material name="green">
    <color rgba="0 0.6 0 100"/>
  </material>
  <link name="base_link">
    <visual>
      <origin rpy="1.57075 0 0" xyz="-0.085 0.1 0"/>
      <geometry>
        <mesh filename="package://tltrpillar/meshes/TLTBB.stl" scale="0.001 0.001 0.001"/>
      </geometry>
      <material name="blue"/>
    </visual>
  </link>
  <link name="mid">
    <visual>
      <origin rpy="1.57075 0 0" xyz="-0.073 0.073 -0.84 "/>
      <geometry>
        <mesh filename="package://tltrpillar/meshes/TLTMB.stl" scale="0.001 0.001 0.001" />
      </geometry>
      <material name="white"/>
    </visual>
  </link>
  <link name="top">
    <visual>
      <origin rpy="1.57075 0 0" xyz="-0.098 0.098 -1.195"/>
      <geometry>
        <mesh filename="package://tltrpillar/meshes/TLTUB.stl" scale="0.001 0.001 0.001"/>
      </geometry>
      <material name="green"/>
    </visual>
  </link>
  <joint name="base_to_mid" type="prismatic">
    <origin xyz="0 0 0" />
    <axis xyz="0 0 1" />
    <limit upper="4" lower="0" effort="10" velocity="10" />
    <parent link="base_link"/>
    <child link="mid"/>
  </joint>
  <joint name="mid_to_top" type="prismatic">
    <origin xyz="0 0 0" />
    <axis xyz="0 0 1" />
    <limit upper="4" lower="0" effort="10" velocity="10" />
    <parent link="mid"/>
    <child link="top"/>
  </joint>
</robot>
